Workbook

Sheet Sheet1
A1: P | B1: 101R (Ohm) | C1: 102R (Ohm) | D1: 103R (Ohm) | E1: 104R (Ohm) | F1: 105R (Ohm) | G1: 106R (Ohm) | H1: 107R (Ohm) | I1: 108R (Ohm) | J1: 109R (Ohm) | K1: 110R (Ohm) | L1: 111R (Ohm) | M1: 112R (Ohm) | N1: 113R (Ohm) | O1: 114R (Ohm) | P1: 115R (Ohm) | Q1: 116R (Ohm) | R1: 117R (Ohm) | S1: 118R (Ohm) | U1: P | V1: 101R (Ohm) | W1: 102R (Ohm) | X1: 103R (Ohm) | Y1: 104R (Ohm) | Z1: 105R (Ohm) | AA1: 106R (Ohm) | AB1: 107R (Ohm) | AC1: 108R (Ohm) | AD1: 109R (Ohm) | AE1: 110R (Ohm) | AF1: 111R (Ohm) | AG1: 112R (Ohm) | AH1: 113R (Ohm) | AI1: 114R (Ohm) | AJ1: 115R (Ohm) | AK1: 116R (Ohm) | AL1: 117R (Ohm) | AM1: 118R (Ohm) | AO1: P | AP1: 101R (Ohm) | AQ1: 102R (Ohm) | AR1: 103R (Ohm) | AS1: 104R (Ohm) | AT1: 105R (Ohm) | AU1: 106R (Ohm) | AV1: 107R (Ohm) | AW1: 108R (Ohm) | AX1: 109R (Ohm) | AY1: 110R (Ohm) | AZ1: 111R (Ohm) | BA1: 112R (Ohm) | BB1: 113R (Ohm) | BC1: 114R (Ohm) | BD1: 115R (Ohm) | BE1: 116R (Ohm) | BF1: 117R (Ohm) | BG1: 118R (Ohm)
A2: 0 | B2: 51.315903 | C2: 79.819956 | D2: 312.78851 | E2: 478.91098 | F2: 185.16277 | G2: 387.32464 | H2: 493.19828 | I2: 396.43516 | J2: 113.18864 | K2: 282.51235 | L2: 606.96644 | M2: 300.29195 | N2: 507.14444 | O2: 172.42134 | P2: 2.9808303 | Q2: 25.515006 | R2: 604.03981 | S2: 230.07957 | U2: 0 | V2: 38.813073 | W2: 68.240074 | X2: 266.73671 | Y2: 320.77307 | Z2: 165.90262 | AA2: 311.47166 | AB2: 411.07757 | AC2: 282.97249 | AD2: 73.341727 | AE2: 187.81345 | AF2: 436.79936 | AG2: 227.7937 | AH2: 459.2898 | AI2: 109.22548 | AJ2: 6.1878577 | AK2: 12.51388 | AL2: 425.62281 | AM2: 190.8945 | AO2: 0 | AP2: 60.585297 | AQ2: 87.296597 | AR2: 320.66872 | AS2: 469.63923 | AT2: 192.23793 | AU2: 391.91631 | AV2: 493.75646 | AW2: 387.57295 | AX2: 118.16404 | AY2: 276.16098 | AZ2: 608.15338 | BA2: 301.55396 | BB2: 509.5507 | BC2: 174.74027 | BD2: 2.9914351 | BE2: 25.083769 | BF2: 601.88498 | BG2: 225.77877
A3: 4 | B3: 77.481873 | C3: 107.69047 | D3: 347.29018 | E3: 504.37288 | F3: 211.57109 | G3: 413.47957 | H3: 511.6218 | I3: 426.44879 | J3: 146.69244 | K3: 319.98184 | L3: 632.87447 | M3: 316.74504 | N3: 517.66056 | O3: 218.8113 | P3: 2.9809225 | Q3: 31.176406 | R3: 630.16388 | S3: 272.74228 | U3: 4 | V3: 61.914788 | W3: 85.599779 | X3: 296.93198 | Y3: 344.43449 | Z3: 190.80414 | AA3: 337.66007 | AB3: 424.40837 | AC3: 311.93214 | AD3: 100.42739 | AE3: 229.91291 | AF3: 466.90248 | AG3: 246.57476 | AH3: 467.40745 | AI3: 148.05906 | AJ3: 6.3505207 | AK3: 22.590182 | AL3: 451.02665 | AM3: 234.35226 | AO3: 4 | AP3: 83.503874 | AQ3: 112.35723 | AR3: 351.03533 | AS3: 495.26703 | AT3: 213.36663 | AU3: 418.06474 | AV3: 511.35093 | AW3: 417.0076 | AX3: 146.56708 | AY3: 312.23852 | AZ3: 635.43286 | BA3: 318.92616 | BB3: 522.64282 | BC3: 219.2805 | BD3: 2.9925126 | BE3: 37.329052 | BF3: 627.52843 | BG3: 264.48674
A4: 8 | B4: 108.40759 | C4: 135.06574 | D4: 382.45677 | E4: 539.75505 | F4: 247.74906 | G4: 445.096 | H4: 535.76706 | I4: 456.19037 | J4: 177.70227 | K4: 361.45288 | L4: 666.41452 | M4: 339.09266 | N4: 526.98895 | O4: 264.40898 | P4: 3.0950585 | Q4: 50.923094 | R4: 660.08933 | S4: 317.45426 | U4: 8 | V4: 82.254606 | W4: 104.74823 | X4: 324.86082 | Y4: 370.10364 | Z4: 208.1521 | AA4: 364.53446 | AB4: 436.99043 | AC4: 347.7639 | AD4: 122.10864 | AE4: 266.91223 | AF4: 501.32404 | AG4: 267.16071 | AH4: 475.50399 | AI4: 186.76605 | AJ4: 6.5153507 | AK4: 36.962731 | AL4: 478.5292 | AM4: 268.15486 | AO4: 8 | AP4: 106.53643 | AQ4: 143.79347 | AR4: 381.29268 | AS4: 524.48575 | AT4: 240.34901 | AU4: 444.7557 | AV4: 529.26496 | AW4: 442.33484 | AX4: 172.77907 | AY4: 347.18493 | AZ4: 664.52967 | BA4: 338.34643 | BB4: 531.25741 | BC4: 257.78406 | BD4: 3.0387506 | BE4: 53.790575 | BF4: 655.13439 | BG4: 302.64849
A5: 12 | B5: 136.4331 | C5: 180.78701 | D5: 420.9908 | E5: 579.93571 | F5: 282.89737 | G5: 480.60939 | H5: 568.90399 | I5: 495.51708 | J5: 207.10876 | K5: 408.02492 | L5: 703.00763 | M5: 367.11113 | N5: 546.68175 | O5: 315.08858 | P5: 4.7403081 | Q5: 76.766944 | R5: 697.01903 | S5: 362.27363 | U5: 12 | V5: 110.40115 | W5: 130.39049 | X5: 355.58967 | Y5: 403.70111 | Z5: 237.60606 | AA5: 395.30564 | AB5: 457.8875 | AC5: 384.03762 | AD5: 150.58276 | AE5: 314.56283 | AF5: 544.18843 | AG5: 290.57787 | AH5: 487.40679 | AI5: 231.38422 | AJ5: 11.262469 | AK5: 60.706662 | AL5: 514.60536 | AM5: 312.46225 | AO5: 12 | AP5: 131.87673 | AQ5: 179.87211 | AR5: 411.29504 | AS5: 559.94276 | AT5: 267.60645 | AU5: 473.38332 | AV5: 558.91662 | AW5: 478.06475 | AX5: 196.28422 | AY5: 384.63765 | AZ5: 694.66887 | BA5: 360.18416 | BB5: 546.16035 | BC5: 300.44701 | BD5: 3.9049977 | BE5: 72.979323 | BF5: 684.30837 | BG5: 342.55736
A6: 16 | B6: 171.01496 | C6: 219.11493 | D6: 457.63557 | E6: 619.08115 | F6: 320.0288 | G6: 512.08809 | H6: 603.63339 | I6: 529.98533 | J6: 232.04724 | K6: 448.23832 | L6: 740.97281 | M6: 393.88631 | N6: 575.65496 | O6: 368.4235 | P6: 11.278004 | Q6: 98.931453 | R6: 732.14884 | S6: 406.6201 | U6: 16 | V6: 135.26546 | W6: 165.86085 | X6: 388.00176 | Y6: 438.23104 | Z6: 261.4675 | AA6: 427.19693 | AB6: 477.39234 | AC6: 416.51082 | AD6: 176.30011 | AE6: 356.71271 | AF6: 584.1888 | AG6: 311.87133 | AH6: 504.03797 | AI6: 271.677 | AJ6: 17.137688 | AK6: 82.936959 | AL6: 547.37003 | AM6: 348.94955 | AO6: 16 | AP6: 161.16332 | AQ6: 216.76042 | AR6: 450.43844 | AS6: 599.70437 | AT6: 300.41095 | AU6: 501.62406 | AV6: 588.54593 | AW6: 510.0622 | AX6: 220.35775 | AY6: 427.19439 | AZ6: 731.20312 | BA6: 384.71876 | BB6: 573.98113 | BC6: 349.46785 | BD6: 9.9247313 | BE6: 98.843364 | BF6: 715.92455 | BG6: 382.46693
A7: 20 | B7: 204.89178 | C7: 258.35217 | D7: 496.31483 | E7: 657.84662 | F7: 351.83675 | G7: 538.25485 | H7: 629.53906 | I7: 558.8647 | J7: 266.98539 | K7: 484.08152 | L7: 776.27517 | M7: 414.92335 | N7: 608.11685 | O7: 412.73304 | P7: 15.276534 | Q7: 122.53454 | R7: 764.17632 | S7: 441.21954 | U7: 20 | V7: 161.32778 | W7: 198.29712 | X7: 423.7326 | Y7: 471.31773 | Z7: 284.39727 | AA7: 454.79427 | AB7: 499.73769 | AC7: 450.05816 | AD7: 203.12282 | AE7: 396.31496 | AF7: 624.46579 | AG7: 331.87076 | AH7: 532.90469 | AI7: 312.38409 | AJ7: 21.640582 | AK7: 98.038216 | AL7: 584.08193 | AM7: 383.66857 | AO7: 20 | AP7: 190.16184 | AQ7: 253.32873 | AR7: 487.91881 | AS7: 637.7547 | AT7: 328.73951 | AU7: 533.54467 | AV7: 614.64385 | AW7: 540.07456 | AX7: 249.02206 | AY7: 461.074 | AZ7: 761.37487 | BA7: 404.32022 | BB7: 598.65549 | BC7: 394.57528 | BD7: 14.677309 | BE7: 118.78864 | BF7: 748.84001 | BG7: 416.04257
A8: 30 | B8: 265.58759 | C8: 345.23261 | D8: 577.38967 | E8: 744.73681 | F8: 431.36952 | G8: 613.19737 | H8: 691.74495 | I8: 638.49435 | J8: 350.21609 | K8: 571.50436 | L8: 849.54898 | M8: 467.6107 | N8: 708.48143 | O8: 517.63043 | P8: 25.953996 | Q8: 175.9097 | R8: 843.12696 | S8: 537.77936 | U8: 30 | V8: 228.03394 | W8: 281.06572 | X8: 508.15363 | Y8: 571.60438 | Z8: 351.17594 | AA8: 527.75371 | AB8: 560.11939 | AC8: 527.14386 | AD8: 286.18249 | AE8: 491.25579 | AF8: 725.41689 | AG8: 388.43517 | AH8: 611.88461 | AI8: 424.00049 | AJ8: 45.866118 | AK8: 147.8347 | AL8: 678.08736 | AM8: 468.69584 | AO8: 30 | AP8: 251.93636 | AQ8: 338.63287 | AR8: 564.85854 | AS8: 721.05535 | AT8: 407.7705 | AU8: 607.43004 | AV8: 671.97014 | AW8: 620.71385 | AX8: 330.62024 | AY8: 551.86535 | AZ8: 839.64467 | BA8: 458.9019 | BB8: 691.0042 | BC8: 497.2903 | BD8: 24.863588 | BE8: 170.27481 | BF8: 833.9165 | BG8: 509.16852
A9: 40 | B9: 350.34414 | C9: 424.25015 | D9: 659.66567 | E9: 828.92076 | F9: 494.24747 | G9: 678.95412 | H9: 767.1943 | I9: 714.33982 | J9: 439.44039 | K9: 645.36052 | L9: 915.06362 | M9: 520.57112 | N9: 842.5576 | O9: 620.88255 | P9: 56.106931 | Q9: 247.72988 | R9: 916.06533 | S9: 638.42943 | U9: 40 | V9: 290.63292 | W9: 354.04997 | X9: 573.77364 | Y9: 661.73783 | Z9: 418.85068 | AA9: 592.12766 | AB9: 622.80949 | AC9: 600.8279 | AD9: 364.75247 | AE9: 565.75492 | AF9: 798.96518 | AG9: 435.48104 | AH9: 710.84189 | AI9: 515.74128 | AJ9: 75.603081 | AK9: 204.75632 | AL9: 754.07561 | AM9: 549.64272 | AO9: 40 | AP9: 321.98598 | AQ9: 410.84632 | AR9: 634.66105 | AS9: 799.11787 | AT9: 469.62267 | AU9: 661.57955 | AV9: 745.83182 | AW9: 694.27405 | AX9: 407.27209 | AY9: 619.49016 | AZ9: 899.33341 | BA9: 506.15514 | BB9: 802.47469 | BC9: 585.84761 | BD9: 52.912317 | BE9: 234.23111 | BF9: 897.52951 | BG9: 600.15287
A10: 60 | B10: 471.52771 | C10: 568.92057 | D10: 785.708 | E10: 958.68074 | F10: 599.68387 | G10: 782.84484 | H10: 885.32199 | I10: 839.66739 | J10: 563.5875 | K10: 768.48104 | L10: 1009.3222 | M10: 585.26919 | N10: 1015.5344 | O10: 792.44348 | P10: 107.15976 | Q10: 398.16096 | R10: 1023.0647 | S10: 767.2344 | U10: 60 | V10: 420.52519 | W10: 485.65649 | X10: 718.24448 | Y10: 817.29767 | Z10: 532.88665 | AA10: 711.8356 | AB10: 748.62951 | AC10: 742.82916 | AD10: 495.51127 | AE10: 704.6845 | AF10: 928.51959 | AG10: 517.47137 | AH10: 889.86147 | AI10: 702.07694 | AJ10: 138.94697 | AK10: 339.92965 | AL10: 902.79231 | AM10: 700.20773 | AO10: 60 | AP10: 454.29967 | AQ10: 556.51257 | AR10: 774.60767 | AS10: 947.2756 | AT10: 580.72623 | AU10: 773.4128 | AV10: 865.35052 | AW10: 828.67376 | AX10: 544.85724 | AY10: 753.32077 | AZ10: 1005.019 | BA10: 582.26087 | BB10: 994.27704 | BC10: 778.46613 | BD10: 107.10221 | BE10: 384.65614 | BF10: 1021.0569 | BG10: 746.94819
A11: 80 | B11: 596.8556 | C11: 722.81719 | D11: 896.54888 | E11: 1071.579 | F11: 709.60664 | G11: 866.64537 | H11: 1001.7574 | I11: 978.89682 | J11: 678.06655 | K11: 881.35066 | L11: 1105.9825 | M11: 640.41366 | N11: 1147.3814 | O11: 935.03548 | P11: 165.73566 | Q11: 553.97434 | R11: 1123.7355 | S11: 919.29886 | U11: 80 | V11: 545.98111 | W11: 627.82343 | X11: 842.12029 | Y11: 955.64198 | Z11: 647.93702 | AA11: 815.0203 | AB11: 861.40844 | AC11: 890.8242 | AD11: 625.60828 | AE11: 834.26924 | AF11: 1046.2686 | AG11: 585.95247 | AH11: 1013.1924 | AI11: 858.23622 | AJ11: 189.15195 | AK11: 481.14342 | AL11: 1022.7852 | AM11: 848.68589 | AO11: 40 | AP11: 361.25317 | AQ11: 440.6524 | AR11: 677.84755 | AS11: 852.45334 | AT11: 507.02861 | AU11: 704.14141 | AV11: 768.81155 | AW11: 730.61726 | AX11: 442.60097 | AY11: 663.71128 | AZ11: 936.40315 | BA11: 533.19523 | BB11: 852.45334 | BC11: 644.49685 | BD11: 59.624785 | BE11: 255.47965 | BF11: 941.94445 | BG11: 661.54673
A12: 100 | B12: 720.69843 | C12: 848.35048 | D12: 1009.3577 | E12: 1173.5757 | F12: 810.81558 | G12: 940.32203 | H12: 1119.361 | I12: 1102.9744 | J12: 810.54429 | K12: 988.57714 | L12: 1202.5815 | M12: 693.19553 | N12: 1272.139 | O12: 1088.4535 | P12: 212.99841 | Q12: 704.43685 | R12: 1221.3889 | S12: 1042.7227 | U12: 100 | V12: 669.31536 | W12: 750.9135 | X12: 952.34658 | Y12: 1069.0037 | Z12: 747.06016 | AA12: 886.05514 | AB12: 978.21519 | AC12: 1022.2234 | AD12: 744.5003 | AE12: 950.76294 | AF12: 1148.5498 | AG12: 647.52951 | AH12: 1128.151 | AI12: 1004.6433 | AJ12: 223.2442 | AK12: 627.74801 | AL12: 1134.3507 | AM12: 984.1984 | AO12: 30 | AP12: 284.05702 | AQ12: 376.70674 | AR12: 608.15437 | AS12: 790.24353 | AT12: 455.3714 | AU12: 656.69411 | AV12: 701.59891 | AW12: 671.21947 | AX12: 367.73985 | AY12: 607.78545 | AZ12: 891.62407 | BA12: 499.12412 | BB12: 732.56115 | BC12: 546.29634 | BD12: 27.98046 | BE12: 184.93723 | BF12: 886.25952 | BG12: 586.88596
A13: 80 | B13: 635.05478 | C13: 767.0079 | D13: 942.48644 | E13: 1117.3889 | F13: 751.74062 | G13: 900.06397 | H13: 1041.8068 | I13: 1023.6304 | J13: 722.37194 | K13: 927.64879 | L13: 1148.1537 | M13: 661.16674 | N13: 1189.4437 | O13: 996.18801 | P13: 173.47378 | Q13: 587.87985 | R13: 1166.1273 | S13: 975.2261 | U13: 120 | V13: 784.05112 | W13: 874.88661 | X13: 1062.1752 | Y13: 1183.2971 | Z13: 855.69351 | AA13: 981.74476 | AB13: 1101.5277 | AC13: 1152.749 | AD13: 863.88001 | AE13: 1063.544 | AF13: 1248.3177 | AG13: 717.27278 | AH13: 1246.9506 | AI13: 1142.6988 | AJ13: 254.97454 | AK13: 777.61585 | AL13: 1239.9611 | AM13: 1111.6903 | AO13: 20 | AP13: 216.22732 | AQ13: 288.9046 | AR13: 522.76524 | AS13: 716.03132 | AT13: 379.12292 | AU13: 591.09855 | AV13: 634.92576 | AW13: 590.22523 | AX13: 273.90747 | AY13: 529.87638 | AZ13: 827.79537 | BA13: 452.59708 | BB13: 613.12214 | BC13: 444.93771 | BD13: 15.736517 | BE13: 126.92069 | BF13: 815.07512 | BG13: 486.92633
... A18: 16 | B18: 167.39942 | C18: 253.97273 | D18: 493.09497 | E18: 716.66939 | F18: 339.37001 | G18: 577.21496 | H18: 622.06993 | I18: 574.1136 | J18: 224.22557 | K18: 509.25293 | L18: 821.52283 | M18: 447.14098 | N18: 587.82419 | O18: 400.09559 | P18: 11.324233 | Q18: 116.16064 | R18: 801.48615 | S18: 466.83684 | U18: 100 | V18: 790.97377 | W18: 936.324 | X18: 1120.9503 | Y18: 1304.1442 | Z18: 910.52338 | AA18: 1070.9997 | AB18: 1154.0786 | AC18: 1199.2275 | AD18: 840.26464 | AE18: 1115.496 | AF18: 1324.9369 | AG18: 774.82747 | AH18: 1242.6213 | AI18: 1178.9379 | AJ18: 241.70862 | AK18: 783.45544 | AL18: 1334.2048 | AM18: 1185.5195 | AO18: 0 | AP18: 22.082764 | AQ18: 67.468858 | AR18: 295.53842 | AS18: 475.52198 | AT18: 159.08357 | AU18: 386.34296 | AV18: 475.77762 | AW18: 373.71094 | AX18: 90.079412 | AY18: 261.19582 | AZ18: 607.38625 | BA18: 299.28033 | BB18: 499.14171 | BC18: 135.13652 | BD18: 2.9785117 | BE18: 21.461932 | BF18: 601.88913 | BG18: 202.77083
A19: 12 | B19: 117.89656 | C19: 196.51737 | D19: 444.58256 | E19: 666.23302 | F19: 287.63805 | G19: 533.51856 | H19: 583.59879 | I19: 526.52505 | J19: 182.64882 | K19: 451.60324 | L19: 778.78655 | M19: 420.72798 | N19: 554.85057 | O19: 336.05136 | P19: 7.204356 | Q19: 85.025342 | R19: 757.37096 | S19: 413.91543 | U19: 80 | V19: 657.34161 | W19: 809.56771 | X19: 1008.1557 | Y19: 1213.745 | Z19: 805.22533 | AA19: 982.60101 | AB19: 1036.3723 | AC19: 1085.4005 | AD19: 694.70786 | AE19: 1003.7526 | AF19: 1245.3055 | AG19: 710.79478 | AH19: 1118.9568 | AI19: 1035.9275 | AJ19: 187.90551 | AK19: 640.57191 | AL19: 1249.278 | AM19: 1060.3261
A20: 8 | B20: 70.371873 | C20: 138.6016 | D20: 396.39082 | E20: 614.81791 | F20: 232.68078 | G20: 486.02127 | H20: 540.80914 | I20: 475.0508 | J20: 140.92386 | K20: 384.85904 | L20: 723.05471 | M20: 386.01014 | N20: 528.9316 | O20: 244.33723 | P20: 3.0502806 | Q20: 58.873303 | R20: 710.44232 | S20: 342.65922 | U20: 60 | V20: 496.12897 | W20: 651.63658 | X20: 871.56013 | Y20: 1098.4281 | Z20: 659.30307 | AA20: 884.59423 | AB20: 893.57495 | AC20: 930.21567 | AD20: 541.58877 | AE20: 861.55544 | AF20: 1139.6295 | AG20: 639.25444 | AH20: 952.35385 | AI20: 841.15916 | AJ20: 117.31503 | AK20: 462.57325 | AL20: 1139.7899 | AM20: 910.91439
A21: 4 | B21: 30.15385 | C21: 99.119637 | D21: 349.79634 | E21: 562.2387 | F21: 185.08135 | G21: 442.48293 | H21: 515.20861 | I21: 425.50142 | J21: 108.39363 | K21: 325.34631 | L21: 673.12968 | M21: 350.54991 | N21: 511.78175 | O21: 179.96071 | P21: 3.3234958 | Q21: 38.169021 | R21: 667.33506 | S21: 279.07631 | U21: 40 | V21: 296.12965 | W21: 441.83259 | X21: 686.46987 | Y21: 943.58939 | Z21: 486.46483 | AA21: 772.70247 | AB21: 752.91278 | AC21: 744.63159 | AD21: 357.84768 | AE21: 688.1325 | AF21: 998.12357 | AG21: 567.41154 | AH21: 725.32978 | AI21: 620.86165 | AJ21: 41.901797 | AK21: 278.97906 | AL21: 1003.0828 | AM21: 686.87079
A22: 0 | B22: 13.944649 | C22: 54.51162 | D22: 292.67785 | E22: 477.2466 | F22: 137.50194 | G22: 374.87741 | H22: 488.00947 | I22: 374.02329 | J22: 81.035467 | K22: 254.95892 | L22: 605.14076 | M22: 301.11249 | N22: 495.80531 | O22: 119.76312 | P22: 2.969607 | Q22: 24.71494 | R22: 600.63014 | S22: 192.80822 | U22: 30 | V22: 199.52324 | W22: 342.79842 | X22: 593.80138 | Y22: 843.56902 | Z22: 400.90642 | AA22: 694.78864 | AB22: 666.34119 | AC22: 651.39199 | AD22: 259.97244 | AE22: 581.39201 | AF22: 922.65932 | AG22: 513.96823 | AH22: 588.38446 | AI22: 468.48863 | AJ22: 27.044806 | AK22: 198.68843 | AL22: 913.11817 | AM22: 577.24717
U23: 20 | V23: 82.136089 | W23: 213.8906 | X23: 472.54795 | Y23: 724.54012 | Z23: 273.90114 | AA23: 601.57855 | AB23: 585.74179 | AC23: 539.11347 | AD23: 155.92486 | AE23: 452.24598 | AF23: 831.55372 | AG23: 449.21272 | AH23: 481.35086 | AI23: 318.70244 | AJ23: 14.588514 | AK23: 122.82675 | AL23: 815.24898 | AM23: 414.44292
U24: 16 | V24: 47.986119 | W24: 170.41774 | X24: 430.72492 | Y24: 675.60528 | Z24: 233.85685 | AA24: 556.9024 | AB24: 554.31613 | AC24: 500.69335 | AD24: 126.61011 | AE24: 394.90377 | AF24: 792.24337 | AG24: 417.14765 | AH24: 458.10692 | AI24: 251.53823 | AJ24: 9.9988658 | AK24: 100.46829 | AL24: 770.35647 | AM24: 350.29518
U25: 12 | V25: 18.003899 | W25: 117.43633 | X25: 376.31693 | Y25: 617.59948 | Z25: 181.78223 | AA25: 507.47739 | AB25: 516.02371 | AC25: 445.33673 | AD25: 89.993024 | AE25: 324.08934 | AF25: 745.58195 | AG25: 379.0717 | AH25: 442.51578 | AI25: 187.19846 | AJ25: 6.7342451 | AK25: 73.300222 | AL25: 714.8476 | AM25: 267.78779
U26: 8 | V26: 3.4019249 | W26: 76.362441 | X26: 302.11486 | Y26: 538.61714 | Z26: 113.28103 | AA26: 441.11391 | AB26: 474.49028 | AC26: 380.49386 | AD26: 55.715328 | AE26: 221.84423 | AF26: 681.70875 | AG26: 329.07541 | AH26: 421.10243 | AI26: 95.501044 | AJ26: 5.769786 | AK26: 42.965849 | AL26: 650.9569 | AM26: 153.74744
U27: 4 | V27: 3.3335445 | W27: 40.465009 | X27: 245.86983 | Y27: 453.48986 | Z27: 72.829449 | AA27: 359.12064 | AB27: 450.51429 | AC27: 325.07676 | AD27: 29.857206 | AE27: 134.11203 | AF27: 604.70698 | AG27: 277.93111 | AH27: 402.16518 | AI27: 25.449146 | AJ27: 3.5503804 | AK27: 23.681466 | AL27: 581.66365 | AM27: 51.363784
U28: 0 | V28: 3.3450716 | W28: 19.660423 | X28: 196.90864 | Y28: 360.61935 | Z28: 48.083437 | AA28: 279.01269 | AB28: 430.17322 | AC28: 275.99357 | AD28: 21.837457 | AE28: 61.900407 | AF28: 536.76166 | AG28: 222.60991 | AH28: 392.88162 | AI28: 3.4593123 | AJ28: 2.7291463 | AK28: 14.392294 | AL28: 506.54499 | AM28: 10.090626

Sheet Sheet2

Sheet 100 loading
A1: P | B1: 101R (Ohm) | C1: 102R (Ohm) | D1: 103R (Ohm) | E1: 104R (Ohm) | F1: 105R (Ohm) | G1: 106R (Ohm) | H1: 107R (Ohm) | I1: 108R (Ohm) | J1: 109R (Ohm) | K1: 110R (Ohm) | L1: 111R (Ohm) | M1: 112R (Ohm) | N1: 113R (Ohm) | O1: 114R (Ohm) | P1: 115R (Ohm) | Q1: 116R (Ohm) | R1: 117R (Ohm) | S1: 118R (Ohm)
A2: 0 | B2: 51.315903 | C2: 79.819956 | D2: 312.78851 | E2: 478.91098 | F2: 185.16277 | G2: 387.32464 | H2: 493.19828 | I2: 396.43516 | J2: 113.18864 | K2: 282.51235 | L2: 606.96644 | M2: 300.29195 | N2: 507.14444 | O2: 172.42134 | P2: 2.9808303 | Q2: 25.515006 | R2: 604.03981 | S2: 230.07957
A3: 4 | B3: 77.481873 | C3: 107.69047 | D3: 347.29018 | E3: 504.37288 | F3: 211.57109 | G3: 413.47957 | H3: 511.6218 | I3: 426.44879 | J3: 146.69244 | K3: 319.98184 | L3: 632.87447 | M3: 316.74504 | N3: 517.66056 | O3: 218.8113 | P3: 2.9809225 | Q3: 31.176406 | R3: 630.16388 | S3: 272.74228
A4: 8 | B4: 108.40759 | C4: 135.06574 | D4: 382.45677 | E4: 539.75505 | F4: 247.74906 | G4: 445.096 | H4: 535.76706 | I4: 456.19037 | J4: 177.70227 | K4: 361.45288 | L4: 666.41452 | M4: 339.09266 | N4: 526.98895 | O4: 264.40898 | P4: 3.0950585 | Q4: 50.923094 | R4: 660.08933 | S4: 317.45426
A5: 12 | B5: 136.4331 | C5: 180.78701 | D5: 420.9908 | E5: 579.93571 | F5: 282.89737 | G5: 480.60939 | H5: 568.90399 | I5: 495.51708 | J5: 207.10876 | K5: 408.02492 | L5: 703.00763 | M5: 367.11113 | N5: 546.68175 | O5: 315.08858 | P5: 4.7403081 | Q5: 76.766944 | R5: 697.01903 | S5: 362.27363
A6: 16 | B6: 171.01496 | C6: 219.11493 | D6: 457.63557 | E6: 619.08115 | F6: 320.0288 | G6: 512.08809 | H6: 603.63339 | I6: 529.98533 | J6: 232.04724 | K6: 448.23832 | L6: 740.97281 | M6: 393.88631 | N6: 575.65496 | O6: 368.4235 | P6: 11.278004 | Q6: 98.931453 | R6: 732.14884 | S6: 406.6201
A7: 20 | B7: 204.89178 | C7: 258.35217 | D7: 496.31483 | E7: 657.84662 | F7: 351.83675 | G7: 538.25485 | H7: 629.53906 | I7: 558.8647 | J7: 266.98539 | K7: 484.08152 | L7: 776.27517 | M7: 414.92335 | N7: 608.11685 | O7: 412.73304 | P7: 15.276534 | Q7: 122.53454 | R7: 764.17632 | S7: 441.21954
A8: 30 | B8: 265.58759 | C8: 345.23261 | D8: 577.38967 | E8: 744.73681 | F8: 431.36952 | G8: 613.19737 | H8: 691.74495 | I8: 638.49435 | J8: 350.21609 | K8: 571.50436 | L8: 849.54898 | M8: 467.6107 | N8: 708.48143 | O8: 517.63043 | P8: 25.953996 | Q8: 175.9097 | R8: 843.12696 | S8: 537.77936
A9: 40 | B9: 350.34414 | C9: 424.25015 | D9: 659.66567 | E9: 828.92076 | F9: 494.24747 | G9: 678.95412 | H9: 767.1943 | I9: 714.33982 | J9: 439.44039 | K9: 645.36052 | L9: 915.06362 | M9: 520.57112 | N9: 842.5576 | O9: 620.88255 | P9: 56.106931 | Q9: 247.72988 | R9: 916.06533 | S9: 638.42943
A10: 60 | B10: 471.52771 | C10: 568.92057 | D10: 785.708 | E10: 958.68074 | F10: 599.68387 | G10: 782.84484 | H10: 885.32199 | I10: 839.66739 | J10: 563.5875 | K10: 768.48104 | L10: 1009.3222 | M10: 585.26919 | N10: 1015.5344 | O10: 792.44348 | P10: 107.15976 | Q10: 398.16096 | R10: 1023.0647 | S10: 767.2344
A11: 80 | B11: 596.8556 | C11: 722.81719 | D11: 896.54888 | E11: 1071.579 | F11: 709.60664 | G11: 866.64537 | H11: 1001.7574 | I11: 978.89682 | J11: 678.06655 | K11: 881.35066 | L11: 1105.9825 | M11: 640.41366 | N11: 1147.3814 | O11: 935.03548 | P11: 165.73566 | Q11: 553.97434 | R11: 1123.7355 | S11: 919.29886
A12: 100 | B12: 720.69843 | C12: 848.35048 | D12: 1009.3577 | E12: 1173.5757 | F12: 810.81558 | G12: 940.32203 | H12: 1119.361 | I12: 1102.9744 | J12: 810.54429 | K12: 988.57714 | L12: 1202.5815 | M12: 693.19553 | N12: 1272.139 | O12: 1088.4535 | P12: 212.99841 | Q12: 704.43685 | R12: 1221.3889 | S12: 1042.7227
B14: =SLOPE($A2:$A12,B2:B12) -> 0.14820331 | C14: =SLOPE($A2:$A12,C2:C12) -> 0.12726832 | D14: =SLOPE($A2:$A12,D2:D12) -> 0.14092589 | E14: =SLOPE($A2:$A12,E2:E12) -> 0.13832576 | F14: =SLOPE($A2:$A12,F2:F12) -> 0.1574638 | G14: =SLOPE($A2:$A12,G2:G12) -> 0.17361345 | H14: =SLOPE($A2:$A12,H2:H12) -> 0.1572324 | I14: =SLOPE($A2:$A12,I2:I12) -> 0.14055515 | ... S14: =SLOPE($A2:$A12,S2:S12) -> 0.12147242
B15: =INTERCEPT($A2:$A12,B2:B12) -> -8.8650949 | C15: =INTERCEPT($A2:$A12,C2:C12) -> -11.374986 | D15: =INTERCEPT($A2:$A12,D2:D12) -> -47.666941 | E15: =INTERCEPT($A2:$A12,E2:E12) -> -68.943448 | F15: =INTERCEPT($A2:$A12,F2:F12) -> -32.855859 | G15: =INTERCEPT($A2:$A12,G2:G12) -> -71.460003 | H15: =INTERCEPT($A2:$A12,H2:H12) -> -77.970671 | I15: =INTERCEPT($A2:$A12,I2:I12) -> -57.568774 | ... S15: =INTERCEPT($A2:$A12,S2:S12) -> -31.912962
B16: =MAX(B30:B40)/MAX($A:$A) -> 0.030570665 | C16: =MAX(C30:C40)/MAX($A:$A) -> 0.034068427 | D16: =MAX(D30:D40)/MAX($A:$A) -> 0.054223124 | E16: =MAX(E30:E40)/MAX($A:$A) -> 0.066076899 | F16: =MAX(F30:F40)/MAX($A:$A) -> 0.051817573 | G16: =MAX(G30:G40)/MAX($A:$A) -> 0.082074563 | H16: =MAX(H30:H40)/MAX($A:$A) -> 0.026571307 | I16: =MAX(I30:I40)/MAX($A:$A) -> 0.028353627 | ... S16: =MAX(S30:S40)/MAX($A:$A) -> 0.056386081
A18: 0 | B18: =B2*B$14+B$15 -> -1.2599081 | C18: =C2*C$14+C$15 -> -1.2164343 | D18: =D2*D$14+D$15 -> -3.5869415 | E18: =E2*E$14+E$15 -> -2.6977226 | F18: =F2*F$14+F$15 -> -3.6994258 | G18: =G2*G$14+G$15 -> -4.2152383 | H18: =H2*H$14+H$15 -> -0.42392041 | I18: =I2*I$14+I$15 -> -1.8477733 | ... S18: =S2*S$14+S$15 -> -3.964639
A19: 4 | B19: =B3*B$14+B$15 -> 2.6179753 | C19: =C3*C$14+C$15 -> 2.3305996 | D19: =D3*D$14+D$15 -> 1.2752361 | E19: =E3*E$14+E$15 -> 0.82431378 | F19: =F3*F$14+F$15 -> 0.4589278 | G19: =G3*G$14+G$15 -> 0.32561038 | H19: =H3*H$14+H$15 -> 2.4728529 | I19: =I3*I$14+I$15 -> 2.3707979 | ... S19: =S3*S$14+S$15 -> 1.2177034
A20: 8 | B20: =B4*B$14+B$15 -> 7.2012693 | C20: =C4*C$14+C$15 -> 5.8146035 | D20: =D4*D$14+D$15 -> 6.2311192 | E20: =E4*E$14+E$15 -> 5.7185799 | F20: =F4*F$14+F$15 -> 6.1556497 | G20: =G4*G$14+G$15 -> 5.8146462 | H20: =H4*H$14+H$15 -> 6.2692706 | I20: =I4*I$14+I$15 -> 6.5511291 | ... S20: =S4*S$14+S$15 -> 6.6489763
A21: 12 | B21: =B5*B$14+B$15 -> 11.354742 | C21: =C5*C$14+C$15 -> 11.633473 | D21: =D5*D$14+D$15 -> 11.661563 | E21: =E5*E$14+E$15 -> 11.2766 | F21: =F5*F$14+F$15 -> 11.690235 | G21: =G5*G$14+G$15 -> 11.98025 | H21: =H5*H$14+H$15 -> 11.479469 | I21: =I5*I$14+I$15 -> 12.078701 | ... S21: =S5*S$14+S$15 -> 12.093293
A22: 16 | B22: =B6*B$14+B$15 -> 16.479889 | C22: =C6*C$14+C$15 -> 16.511404 | D22: =D6*D$14+D$15 -> 16.825759 | E22: =E6*E$14+E$15 -> 16.691424 | F22: =F6*F$14+F$15 -> 17.537091 | G22: =G6*G$14+G$15 -> 17.445374 | H22: =H6*H$14+H$15 -> 16.940056 | I22: =I6*I$14+I$15 -> 16.923392 | ... S22: =S6*S$14+S$15 -> 17.480167
A23: 20 | B23: =B7*B$14+B$15 -> 21.500546 | C23: =C7*C$14+C$15 -> 21.505061 | D23: =D7*D$14+D$15 -> 22.276667 | E23: =E7*E$14+E$15 -> 22.053687 | F23: =F7*F$14+F$15 -> 22.545692 | G23: =G7*G$14+G$15 -> 21.988276 | H23: =H7*H$14+H$15 -> 21.013267 | I23: =I7*I$14+I$15 -> 20.982535 | ... S23: =S7*S$14+S$15 -> 21.683044
A24: 30 | B24: =B8*B$14+B$15 -> 30.495866 | C24: =C8*C$14+C$15 -> 32.562189 | D24: =D8*D$14+D$15 -> 33.702212 | E24: =E8*E$14+E$15 -> 34.072838 | F24: =F8*F$14+F$15 -> 35.069224 | G24: =G8*G$14+G$15 -> 34.999305 | H24: =H8*H$14+H$15 -> 30.794049 | I24: =I8*I$14+I$15 -> 32.174892 | ... S24: =S8*S$14+S$15 -> 33.4124
A25: 40 | B25: =B9*B$14+B$15 -> 43.057067 | C25: =C9*C$14+C$15 -> 42.618619 | D25: =D9*D$14+D$15 -> 45.297031 | E25: =E9*E$14+E$15 -> 45.717646 | F25: =F9*F$14+F$15 -> 44.970225 | G25: =G9*G$14+G$15 -> 46.415561 | H25: =H9*H$14+H$15 -> 42.657131 | I25: =I9*I$14+I$15 -> 42.835363 | ... S25: =S9*S$14+S$15 -> 45.638608
A26: 60 | B26: =B10*B$14+B$15 -> 61.016873 | C26: =C10*C$14+C$15 -> 61.030582 | D26: =D10*D$14+D$15 -> 63.059659 | E26: =E10*E$14+E$15 -> 63.666795 | F26: =F10*F$14+F$15 -> 61.572641 | G26: =G10*G$14+G$15 -> 64.452386 | H26: =H10*H$14+H$15 -> 61.230632 | I26: =I10*I$14+I$15 -> 60.450798 | ... S26: =S10*S$14+S$15 -> 61.284859
A27: 80 | B27: =B11*B$14+B$15 -> 79.590881 | C27: =C11*C$14+C$15 -> 80.616746 | D27: =D11*D$14+D$15 -> 78.680008 | E27: =E11*E$14+E$15 -> 79.283529 | F27: =F11*F$14+F$15 -> 78.881497 | G27: =G11*G$14+G$15 -> 79.001286 | H27: =H11*H$14+H$15 -> 79.538055 | I27: =I11*I$14+I$15 -> 80.020211 | ... S27: =S11*S$14+S$15 -> 79.756498
A28: 100 | B28: =B12*B$14+B$15 -> 97.944799 | C28: =C12*C$14+C$15 -> 96.593157 | D28: =D12*D$14+D$15 -> 94.577688 | E28: =E12*E$14+E$15 -> 93.39231 | F28: =F12*F$14+F$15 -> 94.818243 | G28: =G12*G$14+G$15 -> 91.792544 | H28: =H12*H$14+H$15 -> 98.029139 | I28: =I12*I$14+I$15 -> 97.459954 | ... S28: =S12*S$14+S$15 -> 94.74909
A30: 0 | B30: =ABS(B18-$A18) -> 1.2599081 | C30: =ABS(C18-$A18) -> 1.2164343 | D30: =ABS(D18-$A18) -> 3.5869415 | E30: =ABS(E18-$A18) -> 2.6977226 | F30: =ABS(F18-$A18) -> 3.6994258 | G30: =ABS(G18-$A18) -> 4.2152383 | H30: =ABS(H18-$A18) -> 0.42392041 | I30: =ABS(I18-$A18) -> 1.8477733 | ... S30: =ABS(S18-$A18) -> 3.964639
A31: 4 | B31: =ABS(B19-$A19) -> 1.3820247 | C31: =ABS(C19-$A19) -> 1.6694004 | D31: =ABS(D19-$A19) -> 2.7247639 | E31: =ABS(E19-$A19) -> 3.1756862 | F31: =ABS(F19-$A19) -> 3.5410722 | G31: =ABS(G19-$A19) -> 3.6743896 | H31: =ABS(H19-$A19) -> 1.5271471 | I31: =ABS(I19-$A19) -> 1.6292021 | ... S31: =ABS(S19-$A19) -> 2.7822966
A32: 8 | B32: =ABS(B20-$A20) -> 0.79873074 | C32: =ABS(C20-$A20) -> 2.1853965 | D32: =ABS(D20-$A20) -> 1.7688808 | E32: =ABS(E20-$A20) -> 2.2814201 | F32: =ABS(F20-$A20) -> 1.8443503 | G32: =ABS(G20-$A20) -> 2.1853538 | H32: =ABS(H20-$A20) -> 1.7307294 | I32: =ABS(I20-$A20) -> 1.4488709 | ... S32: =ABS(S20-$A20) -> 1.3510237
A33: 12 | B33: =ABS(B21-$A21) -> 0.64525802 | C33: =ABS(C21-$A21) -> 0.366527 | D33: =ABS(D21-$A21) -> 0.33843724 | E33: =ABS(E21-$A21) -> 0.72340039 | F33: =ABS(F21-$A21) -> 0.30976478 | G33: =ABS(G21-$A21) -> 0.019750439 | H33: =ABS(H21-$A21) -> 0.52053072 | I33: =ABS(I21-$A21) -> 0.078701263 | ... S33: =ABS(S21-$A21) -> 0.093293267
A34: 16 | B34: =ABS(B22-$A22) -> 0.47988902 | C34: =ABS(C22-$A22) -> 0.51140415 | D34: =ABS(D22-$A22) -> 0.82575872 | E34: =ABS(E22-$A22) -> 0.69142358 | F34: =ABS(F22-$A22) -> 1.5370912 | G34: =ABS(G22-$A22) -> 1.4453743 | H34: =ABS(H22-$A22) -> 0.94005577 | I34: =ABS(I22-$A22) -> 0.9233916 | ... S34: =ABS(S22-$A22) -> 1.4801668
A35: 20 | B35: =ABS(B23-$A23) -> 1.5005459 | C35: =ABS(C23-$A23) -> 1.5050612 | D35: =ABS(D23-$A23) -> 2.2766674 | E35: =ABS(E23-$A23) -> 2.0536867 | F35: =ABS(F23-$A23) -> 2.5456922 | G35: =ABS(G23-$A23) -> 1.9882758 | H35: =ABS(H23-$A23) -> 1.0132669 | I35: =ABS(I23-$A23) -> 0.98253489 | ... S35: =ABS(S23-$A23) -> 1.6830444
A36: 30 | B36: =ABS(B24-$A24) -> 0.49586618 | C36: =ABS(C24-$A24) -> 2.5621893 | D36: =ABS(D24-$A24) -> 3.7022118 | E36: =ABS(E24-$A24) -> 4.0728383 | F36: =ABS(F24-$A24) -> 5.0692236 | G36: =ABS(G24-$A24) -> 4.9993052 | H36: =ABS(H24-$A24) -> 0.79404864 | I36: =ABS(I24-$A24) -> 2.1748922 | ... S36: =ABS(S24-$A24) -> 3.4123999
A37: 40 | B37: =ABS(B25-$A25) -> 3.0570665 | C37: =ABS(C25-$A25) -> 2.6186191 | D37: =ABS(D25-$A25) -> 5.2970311 | E37: =ABS(E25-$A25) -> 5.7176463 | F37: =ABS(F25-$A25) -> 4.9702255 | G37: =ABS(G25-$A25) -> 6.4155609 | H37: =ABS(H25-$A25) -> 2.6571307 | I37: =ABS(I25-$A25) -> 2.8353627 | ... S37: =ABS(S25-$A25) -> 5.6386081
A38: 60 | B38: =ABS(B26-$A26) -> 1.0168731 | C38: =ABS(C26-$A26) -> 1.0305815 | D38: =ABS(D26-$A26) -> 3.0596587 | E38: =ABS(E26-$A26) -> 3.6667953 | F38: =ABS(F26-$A26) -> 1.5726407 | G38: =ABS(G26-$A26) -> 4.4523859 | H38: =ABS(H26-$A26) -> 1.2306317 | I38: =ABS(I26-$A26) -> 0.45079802 | ... S38: =ABS(S26-$A26) -> 1.2848592
A39: 80 | B39: =ABS(B27-$A27) -> 0.40911855 | C39: =ABS(C27-$A27) -> 0.6167458 | D39: =ABS(D27-$A27) -> 1.3199919 | E39: =ABS(E27-$A27) -> 0.71647094 | F39: =ABS(F27-$A27) -> 1.1185028 | G39: =ABS(G27-$A27) -> 0.99871368 | H39: =ABS(H27-$A27) -> 0.46194536 | I39: =ABS(I27-$A27) -> 0.02021138 | ... S39: =ABS(S27-$A27) -> 0.24350196
A40: 100 | B40: =ABS(B28-$A28) -> 2.0552007 | C40: =ABS(C28-$A28) -> 3.4068427 | D40: =ABS(D28-$A28) -> 5.4223124 | E40: =ABS(E28-$A28) -> 6.6076899 | F40: =ABS(F28-$A28) -> 5.1817573 | G40: =ABS(G28-$A28) -> 8.2074563 | H40: =ABS(H28-$A28) -> 1.9708608 | I40: =ABS(I28-$A28) -> 2.5400458 | ... S40: =ABS(S28-$A28) -> 5.2509105

Sheet 100 unloading
A1: P | B1: 101R (Ohm) | C1: 102R (Ohm) | D1: 103R (Ohm) | E1: 104R (Ohm) | F1: 105R (Ohm) | G1: 106R (Ohm) | H1: 107R (Ohm) | I1: 108R (Ohm) | J1: 109R (Ohm) | K1: 110R (Ohm) | L1: 111R (Ohm) | M1: 112R (Ohm) | N1: 113R (Ohm) | O1: 114R (Ohm) | P1: 115R (Ohm) | Q1: 116R (Ohm) | R1: 117R (Ohm) | S1: 118R (Ohm)
A2: 0 | B2: 13.944649 | C2: 54.51162 | D2: 292.67785 | E2: 477.2466 | F2: 137.50194 | G2: 374.87741 | H2: 488.00947 | I2: 374.02329 | J2: 81.035467 | K2: 254.95892 | L2: 605.14076 | M2: 301.11249 | N2: 495.80531 | O2: 119.76312 | P2: 2.969607 | Q2: 24.71494 | R2: 600.63014 | S2: 192.80822
A3: 4 | B3: 30.15385 | C3: 99.119637 | D3: 349.79634 | E3: 562.2387 | F3: 185.08135 | G3: 442.48293 | H3: 515.20861 | I3: 425.50142 | J3: 108.39363 | K3: 325.34631 | L3: 673.12968 | M3: 350.54991 | N3: 511.78175 | O3: 179.96071 | P3: 3.3234958 | Q3: 38.169021 | R3: 667.33506 | S3: 279.07631
A4: 8 | B4: 70.371873 | C4: 138.6016 | D4: 396.39082 | E4: 614.81791 | F4: 232.68078 | G4: 486.02127 | H4: 540.80914 | I4: 475.0508 | J4: 140.92386 | K4: 384.85904 | L4: 723.05471 | M4: 386.01014 | N4: 528.9316 | O4: 244.33723 | P4: 3.0502806 | Q4: 58.873303 | R4: 710.44232 | S4: 342.65922
A5: 12 | B5: 117.89656 | C5: 196.51737 | D5: 444.58256 | E5: 666.23302 | F5: 287.63805 | G5: 533.51856 | H5: 583.59879 | I5: 526.52505 | J5: 182.64882 | K5: 451.60324 | L5: 778.78655 | M5: 420.72798 | N5: 554.85057 | O5: 336.05136 | P5: 7.204356 | Q5: 85.025342 | R5: 757.37096 | S5: 413.91543
A6: 16 | B6: 167.39942 | C6: 253.97273 | D6: 493.09497 | E6: 716.66939 | F6: 339.37001 | G6: 577.21496 | H6: 622.06993 | I6: 574.1136 | J6: 224.22557 | K6: 509.25293 | L6: 821.52283 | M6: 447.14098 | N6: 587.82419 | O6: 400.09559 | P6: 11.324233 | Q6: 116.16064 | R6: 801.48615 | S6: 466.83684
A7: 20 | B7: 206.44429 | C7: 299.49443 | D7: 533.13049 | E7: 755.42775 | F7: 384.62839 | G7: 610.93813 | H7: 648.06534 | I7: 612.99347 | J7: 265.33059 | K7: 551.15635 | L7: 851.86043 | M7: 471.93815 | N7: 620.39223 | O7: 451.64166 | P7: 14.987594 | Q7: 138.88779 | R7: 839.08942 | S7: 516.30069
A8: 30 | B8: 296.06184 | C8: 397.79744 | D8: 632.67209 | E8: 845.24876 | F8: 476.24711 | G8: 684.90283 | H8: 734.87931 | I8: 707.91939 | J8: 372.84633 | K8: 640.26584 | L8: 921.00037 | M8: 522.35971 | N8: 767.25333 | O8: 570.98385 | P8: 26.429243 | Q8: 211.89071 | R8: 919.95938 | S8: 637.35312
A9: 40 | B9: 378.86909 | C9: 480.87406 | D9: 713.01829 | E9: 919.75955 | F9: 533.9143 | G9: 744.32744 | H9: 807.28851 | I9: 773.47874 | J9: 450.92079 | K9: 711.20533 | L9: 978.39648 | M9: 559.22309 | N9: 896.73541 | O9: 696.72781 | P9: 57.413012 | Q9: 287.26089 | R9: 980.87224 | S9: 713.92444
A10: 60 | B10: 529.04648 | C10: 644.22874 | D10: 841.34464 | E10: 1034.4361 | F10: 674.30754 | G10: 836.61762 | H10: 930.65432 | I10: 914.63773 | J10: 613.6735 | K10: 834.63454 | L10: 1068.2575 | M10: 624.16226 | N10: 1072.4167 | O10: 850.67807 | P10: 116.51288 | Q10: 445.04013 | R10: 1086.8442 | S10: 852.50387
A11: 80 | B11: 635.05478 | C11: 767.0079 | D11: 942.48644 | E11: 1117.3889 | F11: 751.74062 | G11: 900.06397 | H11: 1041.8068 | I11: 1023.6304 | J11: 722.37194 | K11: 927.64879 | L11: 1148.1537 | M11: 661.16674 | N11: 1189.4437 | O11: 996.18801 | P11: 173.47378 | Q11: 587.87985 | R11: 1166.1273 | S11: 975.2261
A12: 100 | B12: 720.69843 | C12: 848.35048 | D12: 1009.3577 | E12: 1173.5757 | F12: 810.81558 | G12: 940.32203 | H12: 1119.361 | I12: 1102.9744 | J12: 810.54429 | K12: 988.57714 | L12: 1202.5815 | M12: 693.19553 | N12: 1272.139 | O12: 1088.4535 | P12: 212.99841 | Q12: 704.43685 | R12: 1221.3889 | S12: 1042.7227
B14: =SLOPE($A2:$A12,B2:B12) -> 0.13220907 | C14: =SLOPE($A2:$A12,C2:C12) -> 0.11931886 | D14: =SLOPE($A2:$A12,D2:D12) -> 0.13294133 | E14: =SLOPE($A2:$A12,E2:E12) -> 0.13870536 | F14: =SLOPE($A2:$A12,F2:F12) -> 0.13925558 | G14: =SLOPE($A2:$A12,G2:G12) -> 0.16826262 | H14: =SLOPE($A2:$A12,H2:H12) -> 0.15062819 | I14: =SLOPE($A2:$A12,I2:I12) -> 0.1328698 | ... S14: =SLOPE($A2:$A12,S2:S12) -> 0.11321931
B15: =INTERCEPT($A2:$A12,B2:B12) -> -4.4151053 | C15: =INTERCEPT($A2:$A12,C2:C12) -> -11.709967 | D15: =INTERCEPT($A2:$A12,D2:D12) -> -46.715217 | E15: =INTERCEPT($A2:$A12,E2:E12) -> -78.37505 | F15: =INTERCEPT($A2:$A12,F2:F12) -> -27.305999 | G15: =INTERCEPT($A2:$A12,G2:G12) -> -75.448094 | H15: =INTERCEPT($A2:$A12,H2:H12) -> -76.346196 | I15: =INTERCEPT($A2:$A12,I2:I12) -> -57.087718 | ... S15: =INTERCEPT($A2:$A12,S2:S12) -> -32.579715
B16: =MAX(B30:B40)/MAX($A:$A) -> 0.091322344 | C16: =MAX(C30:C40)/MAX($A:$A) -> 0.10485754 | D16: =MAX(D30:D40)/MAX($A:$A) -> 0.12529863 | E16: =MAX(E30:E40)/MAX($A:$A) -> 0.15593809 | F16: =MAX(F30:F40)/MAX($A:$A) -> 0.14395408 | G16: =MAX(G30:G40)/MAX($A:$A) -> 0.1722705 | H16: =MAX(H30:H40)/MAX($A:$A) -> 0.077388795 | I16: =MAX(I30:I40)/MAX($A:$A) -> 0.10535732 | ... S16: =MAX(S30:S40)/MAX($A:$A) -> 0.14523367
A18: 0 | B18: =B2*B$14+B$15 -> -2.5714962 | C18: =C2*C$14+C$15 -> -5.2057022 | D18: =D2*D$14+D$15 -> -7.8062328 | E18: =E2*E$14+E$15 -> -12.178392 | F18: =F2*F$14+F$15 -> -8.1580869 | G18: =G2*G$14+G$15 -> -12.37024 | H18: =H2*H$14+H$15 -> -2.8382126 | I18: =I2*I$14+I$15 -> -7.3913192 | ... S18: =S2*S$14+S$15 -> -10.7501
A19: 4 | B19: =B3*B$14+B$15 -> -0.42849266 | C19: =C3*C$14+C$15 -> 0.11687549 | D19: =D3*D$14+D$15 -> -0.2128246 | E19: =E3*E$14+E$15 -> -0.38953105 | F19: =F3*F$14+F$15 -> -1.5323897 | G19: =G3*G$14+G$15 -> -0.99475906 | H19: =H3*H$14+H$15 -> 1.2587452 | I19: =I3*I$14+I$15 -> -0.55143131 | ... S19: =S3*S$14+S$15 -> -0.98288686
A20: 8 | B20: =B4*B$14+B$15 -> 4.8886948 | C20: =C4*C$14+C$15 -> 4.8278184 | D20: =D4*D$14+D$15 -> 5.9815071 | E20: =E4*E$14+E$15 -> 6.9034866 | F20: =F4*F$14+F$15 -> 5.096097 | G20: =G4*G$14+G$15 -> 6.331116 | H20: =H4*H$14+H$15 -> 5.114906 | I20: =I4*I$14+I$15 -> 6.0321859 | ... S20: =S4*S$14+S$15 -> 6.2159272
A21: 12 | B21: =B5*B$14+B$15 -> 11.17189 | C21: =C5*C$14+C$15 -> 11.738262 | D21: =D5*D$14+D$15 -> 12.388181 | E21: =E5*E$14+E$15 -> 14.035038 | F21: =F5*F$14+F$15 -> 12.749203 | G21: =G5*G$14+G$15 -> 14.323134 | H21: =H5*H$14+H$15 -> 11.560235 | I21: =I5*I$14+I$15 -> 12.871559 | ... S21: =S5*S$14+S$15 -> 14.283506
A22: 16 | B22: =B6*B$14+B$15 -> 17.716617 | C22: =C6*C$14+C$15 -> 18.59377 | D22: =D6*D$14+D$15 -> 18.837485 | E22: =E6*E$14+E$15 -> 21.030832 | F22: =F6*F$14+F$15 -> 19.953167 | G22: =G6*G$14+G$15 -> 21.675606 | H22: =H6*H$14+H$15 -> 17.355073 | I22: =I6*I$14+I$15 -> 19.19464 | ... S22: =S6*S$14+S$15 -> 20.275232
A23: 20 | B23: =B7*B$14+B$15 -> 22.878702 | C23: =C7*C$14+C$15 -> 24.025368 | D23: =D7*D$14+D$15 -> 24.159862 | E23: =E7*E$14+E$15 -> 26.406824 | F23: =F7*F$14+F$15 -> 26.255648 | G23: =G7*G$14+G$15 -> 27.349955 | H23: =H7*H$14+H$15 -> 21.270714 | I23: =I7*I$14+I$15 -> 24.3606 | ... S23: =S7*S$14+S$15 -> 25.875495
A24: 30 | B24: =B8*B$14+B$15 -> 34.726956 | C24: =C8*C$14+C$15 -> 35.754771 | D24: =D8*D$14+D$15 -> 37.393054 | E24: =E8*E$14+E$15 -> 38.86548 | F24: =F8*F$14+F$15 -> 39.014067 | G24: =G8*G$14+G$15 -> 39.795449 | H24: =H8*H$14+H$15 -> 34.347345 | I24: =I8*I$14+I$15 -> 36.973388 | ... S24: =S8*S$14+S$15 -> 39.580968
A25: 40 | B25: =B9*B$14+B$15 -> 45.674826 | C25: =C9*C$14+C$15 -> 45.667378 | D25: =D9*D$14+D$15 -> 48.074384 | E25: =E9*E$14+E$15 -> 49.200526 | F25: =F9*F$14+F$15 -> 47.044544 | G25: =G9*G$14+G$15 -> 49.794388 | H25: =H9*H$14+H$15 -> 45.254213 | I25: =I9*I$14+I$15 -> 45.684245 | ... S25: =S9*S$14+S$15 -> 48.250321
A26: 60 | B26: =B10*B$14+B$15 -> 65.529639 | C26: =C10*C$14+C$15 -> 65.158672 | D26: =D10*D$14+D$15 -> 65.13426 | E26: =E10*E$14+E$15 -> 65.106774 | F26: =F10*F$14+F$15 -> 66.595085 | G26: =G10*G$14+G$15 -> 65.323375 | H26: =H10*H$14+H$15 -> 63.836582 | I26: =I10*I$14+I$15 -> 64.440012 | ... S26: =S10*S$14+S$15 -> 63.940189
A27: 80 | B27: =B11*B$14+B$15 -> 79.544899 | C27: =C11*C$14+C$15 -> 79.808542 | D27: =D11*D$14+D$15 -> 78.580187 | E27: =E11*E$14+E$15 -> 76.61277 | F27: =F11*F$14+F$15 -> 77.378073 | G27: =G11*G$14+G$15 -> 75.999025 | H27: =H11*H$14+H$15 -> 80.579279 | I27: =I11*I$14+I$15 -> 78.921852 | ... S27: =S11*S$14+S$15 -> 77.834715
A28: 100 | B28: =B12*B$14+B$15 -> 90.867766 | C28: =C12*C$14+C$15 -> 89.514246 | D28: =D12*D$14+D$15 -> 87.470137 | E28: =E12*E$14+E$15 -> 84.406191 | F28: =F12*F$14+F$15 -> 85.604592 | G28: =G12*G$14+G$15 -> 82.77295 | H28: =H12*H$14+H$15 -> 92.26112 | I28: =I12*I$14+I$15 -> 89.464268 | ... S28: =S12*S$14+S$15 -> 85.476633
A30: 0 | B30: =ABS(B18-$A18) -> 2.5714962 | C30: =ABS(C18-$A18) -> 5.2057022 | D30: =ABS(D18-$A18) -> 7.8062328 | E30: =ABS(E18-$A18) -> 12.178392 | F30: =ABS(F18-$A18) -> 8.1580869 | G30: =ABS(G18-$A18) -> 12.37024 | H30: =ABS(H18-$A18) -> 2.8382126 | I30: =ABS(I18-$A18) -> 7.3913192 | ... S30: =ABS(S18-$A18) -> 10.7501
A31: 4 | B31: =ABS(B19-$A19) -> 4.4284927 | C31: =ABS(C19-$A19) -> 3.8831245 | D31: =ABS(D19-$A19) -> 4.2128246 | E31: =ABS(E19-$A19) -> 4.389531 | F31: =ABS(F19-$A19) -> 5.5323897 | G31: =ABS(G19-$A19) -> 4.9947591 | H31: =ABS(H19-$A19) -> 2.7412548 | I31: =ABS(I19-$A19) -> 4.5514313 | ... S31: =ABS(S19-$A19) -> 4.9828869
A32: 8 | B32: =ABS(B20-$A20) -> 3.1113052 | C32: =ABS(C20-$A20) -> 3.1721816 | D32: =ABS(D20-$A20) -> 2.0184929 | E32: =ABS(E20-$A20) -> 1.0965134 | F32: =ABS(F20-$A20) -> 2.903903 | G32: =ABS(G20-$A20) -> 1.668884 | H32: =ABS(H20-$A20) -> 2.885094 | I32: =ABS(I20-$A20) -> 1.9678141 | ... S32: =ABS(S20-$A20) -> 1.7840728
A33: 12 | B33: =ABS(B21-$A21) -> 0.82811007 | C33: =ABS(C21-$A21) -> 0.26173841 | D33: =ABS(D21-$A21) -> 0.38818129 | E33: =ABS(E21-$A21) -> 2.0350377 | F33: =ABS(F21-$A21) -> 0.74920262 | G33: =ABS(G21-$A21) -> 2.3231341 | H33: =ABS(H21-$A21) -> 0.43976506 | I33: =ABS(I21-$A21) -> 0.87155915 | ... S33: =ABS(S21-$A21) -> 2.2835059
A34: 16 | B34: =ABS(B22-$A22) -> 1.7166165 | C34: =ABS(C22-$A22) -> 2.5937705 | D34: =ABS(D22-$A22) -> 2.8374853 | E34: =ABS(E22-$A22) -> 5.0308325 | F34: =ABS(F22-$A22) -> 3.9531671 | G34: =ABS(G22-$A22) -> 5.6756057 | H34: =ABS(H22-$A22) -> 1.3550728 | I34: =ABS(I22-$A22) -> 3.1946395 | ... S34: =ABS(S22-$A22) -> 4.2752318
A35: 20 | B35: =ABS(B23-$A23) -> 2.8787023 | C35: =ABS(C23-$A23) -> 4.0253678 | D35: =ABS(D23-$A23) -> 4.1598616 | E35: =ABS(E23-$A23) -> 6.4068243 | F35: =ABS(F23-$A23) -> 6.2556483 | G35: =ABS(G23-$A23) -> 7.3499548 | H35: =ABS(H23-$A23) -> 1.2707145 | I35: =ABS(I23-$A23) -> 4.3606004 | ... S35: =ABS(S23-$A23) -> 5.8754955
A36: 30 | B36: =ABS(B24-$A24) -> 4.7269564 | C36: =ABS(C24-$A24) -> 5.7547706 | D36: =ABS(D24-$A24) -> 7.3930537 | E36: =ABS(E24-$A24) -> 8.8654801 | F36: =ABS(F24-$A24) -> 9.0140669 | G36: =ABS(G24-$A24) -> 9.7954489 | H36: =ABS(H24-$A24) -> 4.3473452 | I36: =ABS(I24-$A24) -> 6.9733879 | ... S36: =ABS(S24-$A24) -> 9.5809684
A37: 40 | B37: =ABS(B25-$A25) -> 5.6748258 | C37: =ABS(C25-$A25) -> 5.6673778 | D37: =ABS(D25-$A25) -> 8.0743843 | E37: =ABS(E25-$A25) -> 9.2005259 | F37: =ABS(F25-$A25) -> 7.0445443 | G37: =ABS(G25-$A25) -> 9.7943885 | H37: =ABS(H25-$A25) -> 5.2542129 | I37: =ABS(I25-$A25) -> 5.6842454 | ... S37: =ABS(S25-$A25) -> 8.2503211
A38: 60 | B38: =ABS(B26-$A26) -> 5.5296386 | C38: =ABS(C26-$A26) -> 5.1586721 | D38: =ABS(D26-$A26) -> 5.1342604 | E38: =ABS(E26-$A26) -> 5.1067743 | F38: =ABS(F26-$A26) -> 6.5950855 | G38: =ABS(G26-$A26) -> 5.3233753 | H38: =ABS(H26-$A26) -> 3.8365816 | I38: =ABS(I26-$A26) -> 4.4400118 | ... S38: =ABS(S26-$A26) -> 3.9401893
A39: 80 | B39: =ABS(B27-$A27) -> 0.45510119 | C39: =ABS(C27-$A27) -> 0.19145801 | D39: =ABS(D27-$A27) -> 1.4198132 | E39: =ABS(E27-$A27) -> 3.38723 | F39: =ABS(F27-$A27) -> 2.6219269 | G39: =ABS(G27-$A27) -> 4.0009748 | H39: =ABS(H27-$A27) -> 0.57927892 | I39: =ABS(I27-$A27) -> 1.0781476 | ... S39: =ABS(S27-$A27) -> 2.1652847
A40: 100 | B40: =ABS(B28-$A28) -> 9.1322344 | C40: =ABS(C28-$A28) -> 10.485754 | D40: =ABS(D28-$A28) -> 12.529863 | E40: =ABS(E28-$A28) -> 15.593809 | F40: =ABS(F28-$A28) -> 14.395408 | G40: =ABS(G28-$A28) -> 17.22705 | H40: =ABS(H28-$A28) -> 7.7388795 | I40: =ABS(I28-$A28) -> 10.535732 | ... S40: =ABS(S28-$A28) -> 14.523367

Sheet 100both
A1: P | B1: 101R (Ohm) | C1: 102R (Ohm) | D1: 103R (Ohm) | E1: 104R (Ohm) | F1: 105R (Ohm) | G1: 106R (Ohm) | H1: 107R (Ohm) | I1: 108R (Ohm) | J1: 109R (Ohm) | K1: 110R (Ohm) | L1: 111R (Ohm) | M1: 112R (Ohm) | N1: 113R (Ohm) | O1: 114R (Ohm) | P1: 115R (Ohm) | Q1: 116R (Ohm) | R1: 117R (Ohm) | S1: 118R (Ohm)
A2: =AVERAGE('100 loading'!A2,'100 unloading'!A2) -> 0 | B2: =AVERAGE('100 loading'!B2,'100 unloading'!B2) -> 32.630276 | C2: =AVERAGE('100 loading'!C2,'100 unloading'!C2) -> 67.165788 | D2: =AVERAGE('100 loading'!D2,'100 unloading'!D2) -> 302.73318 | E2: =AVERAGE('100 loading'!E2,'100 unloading'!E2) -> 478.07879 | F2: =AVERAGE('100 loading'!F2,'100 unloading'!F2) -> 161.33236 | G2: =AVERAGE('100 loading'!G2,'100 unloading'!G2) -> 381.10102 | H2: =AVERAGE('100 loading'!H2,'100 unloading'!H2) -> 490.60388 | ... S2: =AVERAGE('100 loading'!S2,'100 unloading'!S2) -> 211.4439
A3: =AVERAGE('100 loading'!A3,'100 unloading'!A3) -> 4 | B3: =AVERAGE('100 loading'!B3,'100 unloading'!B3) -> 53.817862 | C3: =AVERAGE('100 loading'!C3,'100 unloading'!C3) -> 103.40505 | D3: =AVERAGE('100 loading'!D3,'100 unloading'!D3) -> 348.54326 | E3: =AVERAGE('100 loading'!E3,'100 unloading'!E3) -> 533.30579 | F3: =AVERAGE('100 loading'!F3,'100 unloading'!F3) -> 198.32622 | G3: =AVERAGE('100 loading'!G3,'100 unloading'!G3) -> 427.98125 | H3: =AVERAGE('100 loading'!H3,'100 unloading'!H3) -> 513.4152 | ... S3: =AVERAGE('100 loading'!S3,'100 unloading'!S3) -> 275.90929
A4: =AVERAGE('100 loading'!A4,'100 unloading'!A4) -> 8 | B4: =AVERAGE('100 loading'!B4,'100 unloading'!B4) -> 89.389732 | C4: =AVERAGE('100 loading'!C4,'100 unloading'!C4) -> 136.83367 | D4: =AVERAGE('100 loading'!D4,'100 unloading'!D4) -> 389.42379 | E4: =AVERAGE('100 loading'!E4,'100 unloading'!E4) -> 577.28648 | F4: =AVERAGE('100 loading'!F4,'100 unloading'!F4) -> 240.21492 | G4: =AVERAGE('100 loading'!G4,'100 unloading'!G4) -> 465.55863 | H4: =AVERAGE('100 loading'!H4,'100 unloading'!H4) -> 538.2881 | ... S4: =AVERAGE('100 loading'!S4,'100 unloading'!S4) -> 330.05674
A5: =AVERAGE('100 loading'!A5,'100 unloading'!A5) -> 12 | B5: =AVERAGE('100 loading'!B5,'100 unloading'!B5) -> 127.16483 | C5: =AVERAGE('100 loading'!C5,'100 unloading'!C5) -> 188.65219 | D5: =AVERAGE('100 loading'!D5,'100 unloading'!D5) -> 432.78668 | E5: =AVERAGE('100 loading'!E5,'100 unloading'!E5) -> 623.08436 | F5: =AVERAGE('100 loading'!F5,'100 unloading'!F5) -> 285.26771 | G5: =AVERAGE('100 loading'!G5,'100 unloading'!G5) -> 507.06397 | H5: =AVERAGE('100 loading'!H5,'100 unloading'!H5) -> 576.25139 | ... S5: =AVERAGE('100 loading'!S5,'100 unloading'!S5) -> 388.09453
A6: =AVERAGE('100 loading'!A6,'100 unloading'!A6) -> 16 | B6: =AVERAGE('100 loading'!B6,'100 unloading'!B6) -> 169.20719 | C6: =AVERAGE('100 loading'!C6,'100 unloading'!C6) -> 236.54383 | D6: =AVERAGE('100 loading'!D6,'100 unloading'!D6) -> 475.36527 | E6: =AVERAGE('100 loading'!E6,'100 unloading'!E6) -> 667.87527 | F6: =AVERAGE('100 loading'!F6,'100 unloading'!F6) -> 329.69941 | G6: =AVERAGE('100 loading'!G6,'100 unloading'!G6) -> 544.65152 | H6: =AVERAGE('100 loading'!H6,'100 unloading'!H6) -> 612.85166 | ... S6: =AVERAGE('100 loading'!S6,'100 unloading'!S6) -> 436.72847
A7: =AVERAGE('100 loading'!A7,'100 unloading'!A7) -> 20 | B7: =AVERAGE('100 loading'!B7,'100 unloading'!B7) -> 205.66803 | C7: =AVERAGE('100 loading'!C7,'100 unloading'!C7) -> 278.9233 | D7: =AVERAGE('100 loading'!D7,'100 unloading'!D7) -> 514.72266 | E7: =AVERAGE('100 loading'!E7,'100 unloading'!E7) -> 706.63719 | F7: =AVERAGE('100 loading'!F7,'100 unloading'!F7) -> 368.23257 | G7: =AVERAGE('100 loading'!G7,'100 unloading'!G7) -> 574.59649 | H7: =AVERAGE('100 loading'!H7,'100 unloading'!H7) -> 638.8022 | ... S7: =AVERAGE('100 loading'!S7,'100 unloading'!S7) -> 478.76012
A8: =AVERAGE('100 loading'!A8,'100 unloading'!A8) -> 30 | B8: =AVERAGE('100 loading'!B8,'100 unloading'!B8) -> 280.82472 | C8: =AVERAGE('100 loading'!C8,'100 unloading'!C8) -> 371.51502 | D8: =AVERAGE('100 loading'!D8,'100 unloading'!D8) -> 605.03088 | E8: =AVERAGE('100 loading'!E8,'100 unloading'!E8) -> 794.99279 | F8: =AVERAGE('100 loading'!F8,'100 unloading'!F8) -> 453.80832 | G8: =AVERAGE('100 loading'!G8,'100 unloading'!G8) -> 649.0501 | H8: =AVERAGE('100 loading'!H8,'100 unloading'!H8) -> 713.31213 | ... S8: =AVERAGE('100 loading'!S8,'100 unloading'!S8) -> 587.56624
A9: =AVERAGE('100 loading'!A9,'100 unloading'!A9) -> 40 | B9: =AVERAGE('100 loading'!B9,'100 unloading'!B9) -> 364.60661 | C9: =AVERAGE('100 loading'!C9,'100 unloading'!C9) -> 452.5621 | D9: =AVERAGE('100 loading'!D9,'100 unloading'!D9) -> 686.34198 | E9: =AVERAGE('100 loading'!E9,'100 unloading'!E9) -> 874.34016 | F9: =AVERAGE('100 loading'!F9,'100 unloading'!F9) -> 514.08089 | G9: =AVERAGE('100 loading'!G9,'100 unloading'!G9) -> 711.64078 | H9: =AVERAGE('100 loading'!H9,'100 unloading'!H9) -> 787.24141 | ... S9: =AVERAGE('100 loading'!S9,'100 unloading'!S9) -> 676.17694
A10: =AVERAGE('100 loading'!A10,'100 unloading'!A10) -> 60 | B10: =AVERAGE('100 loading'!B10,'100 unloading'!B10) -> 500.28709 | C10: =AVERAGE('100 loading'!C10,'100 unloading'!C10) -> 606.57465 | D10: =AVERAGE('100 loading'!D10,'100 unloading'!D10) -> 813.52632 | E10: =AVERAGE('100 loading'!E10,'100 unloading'!E10) -> 996.55841 | F10: =AVERAGE('100 loading'!F10,'100 unloading'!F10) -> 636.9957 | G10: =AVERAGE('100 loading'!G10,'100 unloading'!G10) -> 809.73123 | H10: =AVERAGE('100 loading'!H10,'100 unloading'!H10) -> 907.98816 | ... S10: =AVERAGE('100 loading'!S10,'100 unloading'!S10) -> 809.86914
A11: =AVERAGE('100 loading'!A11,'100 unloading'!A11) -> 80 | B11: =AVERAGE('100 loading'!B11,'100 unloading'!B11) -> 615.95519 | C11: =AVERAGE('100 loading'!C11,'100 unloading'!C11) -> 744.91254 | D11: =AVERAGE('100 loading'!D11,'100 unloading'!D11) -> 919.51766 | E11: =AVERAGE('100 loading'!E11,'100 unloading'!E11) -> 1094.4839 | F11: =AVERAGE('100 loading'!F11,'100 unloading'!F11) -> 730.67363 | G11: =AVERAGE('100 loading'!G11,'100 unloading'!G11) -> 883.35467 | H11: =AVERAGE('100 loading'!H11,'100 unloading'!H11) -> 1021.7821 | ... S11: =AVERAGE('100 loading'!S11,'100 unloading'!S11) -> 947.26248
A12: =AVERAGE('100 loading'!A12,'100 unloading'!A12) -> 100 | B12: =AVERAGE('100 loading'!B12,'100 unloading'!B12) -> 720.69843 | C12: =AVERAGE('100 loading'!C12,'100 unloading'!C12) -> 848.35048 | D12: =AVERAGE('100 loading'!D12,'100 unloading'!D12) -> 1009.3577 | E12: =AVERAGE('100 loading'!E12,'100 unloading'!E12) -> 1173.5757 | F12: =AVERAGE('100 loading'!F12,'100 unloading'!F12) -> 810.81558 | G12: =AVERAGE('100 loading'!G12,'100 unloading'!G12) -> 940.32203 | H12: =AVERAGE('100 loading'!H12,'100 unloading'!H12) -> 1119.361 | ... S12: =AVERAGE('100 loading'!S12,'100 unloading'!S12) -> 1042.7227
B14: =SLOPE($A2:$A12,B2:B12) -> 0.14012157 | C14: =SLOPE($A2:$A12,C2:C12) -> 0.12350841 | D14: =SLOPE($A2:$A12,D2:D12) -> 0.13715239 | E14: =SLOPE($A2:$A12,E2:E12) -> 0.13938665 | F14: =SLOPE($A2:$A12,F2:F12) -> 0.14842229 | G14: =SLOPE($A2:$A12,G2:G12) -> 0.17191046 | H14: =SLOPE($A2:$A12,H2:H12) -> 0.1541058 | I14: =SLOPE($A2:$A12,I2:I12) -> 0.13714258 | ... S14: =SLOPE($A2:$A12,S2:S12) -> 0.11782053
B15: =INTERCEPT($A2:$A12,B2:B12) -> -6.619926 | C15: =INTERCEPT($A2:$A12,C2:C12) -> -11.67369 | D15: =INTERCEPT($A2:$A12,D2:D12) -> -47.375184 | E15: =INTERCEPT($A2:$A12,E2:E12) -> -74.327709 | F15: =INTERCEPT($A2:$A12,F2:F12) -> -30.177763 | G15: =INTERCEPT($A2:$A12,G2:G12) -> -74.121049 | H15: =INTERCEPT($A2:$A12,H2:H12) -> -77.318374 | I15: =INTERCEPT($A2:$A12,I2:I12) -> -57.679792 | ... S15: =INTERCEPT($A2:$A12,S2:S12) -> -32.606522
B16: =MAX(B30:B40)/MAX($A:$A) -> 0.056345309 | C16: =MAX(C30:C40)/MAX($A:$A) -> 0.068952749 | D16: =MAX(D30:D40)/MAX($A:$A) -> 0.089393622 | E16: =MAX(E30:E40)/MAX($A:$A) -> 0.10746913 | F16: =MAX(F30:F40)/MAX($A:$A) -> 0.098346582 | G16: =MAX(G30:G40)/MAX($A:$A) -> 0.12469853 | H16: =MAX(H30:H40)/MAX($A:$A) -> 0.04818356 | I16: =MAX(I30:I40)/MAX($A:$A) -> 0.064150325 | ... S16: =MAX(S30:S40)/MAX($A:$A) -> 0.097523811
A18: 0 | B18: =B2*B$14+B$15 -> -2.0477205 | C18: =C2*C$14+C$15 -> -3.3781509 | D18: =D2*D$14+D$15 -> -5.8546029 | E18: =E2*E$14+E$15 -> -7.6899069 | F18: =F2*F$14+F$15 -> -6.2324452 | G18: =G2*G$14+G$15 -> -8.605795 | H18: =H2*H$14+H$15 -> -1.7134698 | I18: =I2*I$14+I$15 -> -4.8484613 | ... S18: =S2*S$14+S$15 -> -7.6940896
A19: 4 | B19: =B3*B$14+B$15 -> 0.92111724 | C19: =C3*C$14+C$15 -> 1.0977031 | D19: =D3*D$14+D$15 -> 0.42835883 | E19: =E3*E$14+E$15 -> 0.0080001095 | F19: =F3*F$14+F$15 -> -0.74173197 | G19: =G3*G$14+G$15 -> -0.54659371 | H19: =H3*H$14+H$15 -> 1.8018883 | I19: =I3*I$14+I$15 -> 0.73953401 | ... S19: =S3*S$14+S$15 -> -0.098742385
A20: 8 | B20: =B4*B$14+B$15 -> 5.9055036 | C20: =C4*C$14+C$15 -> 5.2264179 | D20: =D4*D$14+D$15 -> 6.0352218 | E20: =E4*E$14+E$15 -> 6.1383214 | F20: =F4*F$14+F$15 -> 5.4754858 | G20: =G4*G$14+G$15 -> 5.9133513 | H20: =H4*H$14+H$15 -> 5.6349456 | I20: =I4*I$14+I$15 -> 6.1766177 | ... S20: =S4*S$14+S$15 -> 6.2809388
A21: 12 | B21: =B5*B$14+B$15 -> 11.19861 | C21: =C5*C$14+C$15 -> 11.626441 | D21: =D5*D$14+D$15 -> 11.982546 | E21: =E5*E$14+E$15 -> 12.521935 | F21: =F5*F$14+F$15 -> 12.162323 | G21: =G5*G$14+G$15 -> 13.048554 | H21: =H5*H$14+H$15 -> 11.485309 | I21: =I5*I$14+I$15 -> 12.402957 | ... S21: =S5*S$14+S$15 -> 13.118982
A22: 16 | B22: =B6*B$14+B$15 -> 17.089651 | C22: =C6*C$14+C$15 -> 17.541462 | D22: =D6*D$14+D$15 -> 17.822301 | E22: =E6*E$14+E$15 -> 18.76519 | F22: =F6*F$14+F$15 -> 18.756977 | G22: =G6*G$14+G$15 -> 19.510247 | H22: =H6*H$14+H$15 -> 17.125623 | I22: =I6*I$14+I$15 -> 18.029698 | ... S22: =S6*S$14+S$15 -> 18.849058
A23: 20 | B23: =B7*B$14+B$15 -> 22.198602 | C23: =C7*C$14+C$15 -> 22.775682 | D23: =D7*D$14+D$15 -> 23.220261 | E23: =E7*E$14+E$15 -> 24.168084 | F23: =F7*F$14+F$15 -> 24.476158 | G23: =G7*G$14+G$15 -> 24.6581 | H23: =H7*H$14+H$15 -> 21.124752 | I23: =I7*I$14+I$15 -> 22.676036 | ... S23: =S7*S$14+S$15 -> 23.801249
A24: 30 | B24: =B8*B$14+B$15 -> 32.729674 | C24: =C8*C$14+C$15 -> 34.211538 | D24: =D8*D$14+D$15 -> 35.60625 | E24: =E8*E$14+E$15 -> 36.483675 | F24: =F8*F$14+F$15 -> 37.177506 | G24: =G8*G$14+G$15 -> 37.457455 | H24: =H8*H$14+H$15 -> 32.607164 | I24: =I8*I$14+I$15 -> 34.645537 | ... S24: =S8*S$14+S$15 -> 36.620845
A25: 40 | B25: =B9*B$14+B$15 -> 44.469325 | C25: =C9*C$14+C$15 -> 44.221534 | D25: =D9*D$14+D$15 -> 46.758262 | E25: =E9*E$14+E$15 -> 47.543639 | F25: =F9*F$14+F$15 -> 46.123299 | G25: =G9*G$14+G$15 -> 48.217448 | H25: =H9*H$14+H$15 -> 44.000095 | I25: =I9*I$14+I$15 -> 44.341848 | ... S25: =S9*S$14+S$15 -> 47.061004
A26: 60 | B26: =B10*B$14+B$15 -> 63.481087 | C26: =C10*C$14+C$15 -> 63.243378 | D26: =D10*D$14+D$15 -> 64.201899 | E26: =E10*E$14+E$15 -> 64.579233 | F26: =F10*F$14+F$15 -> 64.366597 | G26: =G10*G$14+G$15 -> 65.080222 | H26: =H10*H$14+H$15 -> 62.60787 | I26: =I10*I$14+I$15 -> 62.615176 | ... S26: =S10*S$14+S$15 -> 62.81269
A27: 80 | B27: =B11*B$14+B$15 -> 79.688682 | C27: =C11*C$14+C$15 -> 80.329271 | D27: =D11*D$14+D$15 -> 78.738865 | E27: =E11*E$14+E$15 -> 78.228742 | F27: =F11*F$14+F$15 -> 78.270489 | G27: =G11*G$14+G$15 -> 77.736863 | H27: =H11*H$14+H$15 -> 80.144179 | I27: =I11*I$14+I$15 -> 79.63609 | ... S27: =S11*S$14+S$15 -> 79.000447
A28: 100 | B28: =B12*B$14+B$15 -> 94.365469 | C28: =C12*C$14+C$15 -> 93.104725 | D28: =D12*D$14+D$15 -> 91.060638 | E28: =E12*E$14+E$15 -> 89.253087 | F28: =F12*F$14+F$15 -> 90.165342 | G28: =G12*G$14+G$15 -> 87.530147 | H28: =H12*H$14+H$15 -> 95.181644 | I28: =I12*I$14+I$15 -> 93.584967 | ... S28: =S12*S$14+S$15 -> 90.247619
A30: 0 | B30: =ABS(B18-$A18) -> 2.0477205 | C30: =ABS(C18-$A18) -> 3.3781509 | D30: =ABS(D18-$A18) -> 5.8546029 | E30: =ABS(E18-$A18) -> 7.6899069 | F30: =ABS(F18-$A18) -> 6.2324452 | G30: =ABS(G18-$A18) -> 8.605795 | H30: =ABS(H18-$A18) -> 1.7134698 | I30: =ABS(I18-$A18) -> 4.8484613 | ... S30: =ABS(S18-$A18) -> 7.6940896
A31: 4 | B31: =ABS(B19-$A19) -> 3.0788828 | C31: =ABS(C19-$A19) -> 2.9022969 | D31: =ABS(D19-$A19) -> 3.5716412 | E31: =ABS(E19-$A19) -> 3.9919999 | F31: =ABS(F19-$A19) -> 4.741732 | G31: =ABS(G19-$A19) -> 4.5465937 | H31: =ABS(H19-$A19) -> 2.1981117 | I31: =ABS(I19-$A19) -> 3.260466 | ... S31: =ABS(S19-$A19) -> 4.0987424
A32: 8 | B32: =ABS(B20-$A20) -> 2.0944964 | C32: =ABS(C20-$A20) -> 2.7735821 | D32: =ABS(D20-$A20) -> 1.9647782 | E32: =ABS(E20-$A20) -> 1.8616786 | F32: =ABS(F20-$A20) -> 2.5245142 | G32: =ABS(G20-$A20) -> 2.0866487 | H32: =ABS(H20-$A20) -> 2.3650544 | I32: =ABS(I20-$A20) -> 1.8233823 | ... S32: =ABS(S20-$A20) -> 1.7190612
A33: 12 | B33: =ABS(B21-$A21) -> 0.80139045 | C33: =ABS(C21-$A21) -> 0.37355947 | D33: =ABS(D21-$A21) -> 0.017454066 | E33: =ABS(E21-$A21) -> 0.52193498 | F33: =ABS(F21-$A21) -> 0.16232319 | G33: =ABS(G21-$A21) -> 1.0485542 | H33: =ABS(H21-$A21) -> 0.51469066 | I33: =ABS(I21-$A21) -> 0.4029572 | ... S33: =ABS(S21-$A21) -> 1.1189815
A34: 16 | B34: =ABS(B22-$A22) -> 1.0896511 | C34: =ABS(C22-$A22) -> 1.5414615 | D34: =ABS(D22-$A22) -> 1.8223009 | E34: =ABS(E22-$A22) -> 2.76519 | F34: =ABS(F22-$A22) -> 2.7569774 | G34: =ABS(G22-$A22) -> 3.5102474 | H34: =ABS(H22-$A22) -> 1.1256229 | I34: =ABS(I22-$A22) -> 2.0296979 | ... S34: =ABS(S22-$A22) -> 2.8490584
A35: 20 | B35: =ABS(B23-$A23) -> 2.1986018 | C35: =ABS(C23-$A23) -> 2.7756819 | D35: =ABS(D23-$A23) -> 3.2202614 | E35: =ABS(E23-$A23) -> 4.1680835 | F35: =ABS(F23-$A23) -> 4.4761578 | G35: =ABS(G23-$A23) -> 4.6581005 | H35: =ABS(H23-$A23) -> 1.1247519 | I35: =ABS(I23-$A23) -> 2.6760363 | ... S35: =ABS(S23-$A23) -> 3.8012492
A36: 30 | B36: =ABS(B24-$A24) -> 2.7296744 | C36: =ABS(C24-$A24) -> 4.2115382 | D36: =ABS(D24-$A24) -> 5.6062498 | E36: =ABS(E24-$A24) -> 6.4836752 | F36: =ABS(F24-$A24) -> 7.1775059 | G36: =ABS(G24-$A24) -> 7.4574554 | H36: =ABS(H24-$A24) -> 2.6071643 | I36: =ABS(I24-$A24) -> 4.6455372 | ... S36: =ABS(S24-$A24) -> 6.6208447
A37: 40 | B37: =ABS(B25-$A25) -> 4.469325 | C37: =ABS(C25-$A25) -> 4.2215336 | D37: =ABS(D25-$A25) -> 6.7582621 | E37: =ABS(E25-$A25) -> 7.5436392 | F37: =ABS(F25-$A25) -> 6.123299 | G37: =ABS(G25-$A25) -> 8.2174478 | H37: =ABS(H25-$A25) -> 4.0000947 | I37: =ABS(I25-$A25) -> 4.3418481 | ... S37: =ABS(S25-$A25) -> 7.0610041
A38: 60 | B38: =ABS(B26-$A26) -> 3.4810866 | C38: =ABS(C26-$A26) -> 3.2433784 | D38: =ABS(D26-$A26) -> 4.201899 | E38: =ABS(E26-$A26) -> 4.5792331 | F38: =ABS(F26-$A26) -> 4.3665974 | G38: =ABS(G26-$A26) -> 5.0802221 | H38: =ABS(H26-$A26) -> 2.6078697 | I38: =ABS(I26-$A26) -> 2.6151759 | ... S38: =ABS(S26-$A26) -> 2.8126898
A39: 80 | B39: =ABS(B27-$A27) -> 0.31131779 | C39: =ABS(C27-$A27) -> 0.32927058 | D39: =ABS(D27-$A27) -> 1.2611347 | E39: =ABS(E27-$A27) -> 1.7712579 | F39: =ABS(F27-$A27) -> 1.7295111 | G39: =ABS(G27-$A27) -> 2.2631369 | H39: =ABS(H27-$A27) -> 0.14417892 | I39: =ABS(I27-$A27) -> 0.36391037 | ... S39: =ABS(S27-$A27) -> 0.99955349
A40: 100 | B40: =ABS(B28-$A28) -> 5.6345309 | C40: =ABS(C28-$A28) -> 6.8952749 | D40: =ABS(D28-$A28) -> 8.9393622 | E40: =ABS(E28-$A28) -> 10.746913 | F40: =ABS(F28-$A28) -> 9.8346582 | G40: =ABS(G28-$A28) -> 12.469853 | H40: =ABS(H28-$A28) -> 4.818356 | I40: =ABS(I28-$A28) -> 6.4150325 | ... S40: =ABS(S28-$A28) -> 9.7523811

Sheet 60 loading
A1: P | B1: 101R (Ohm) | C1: 102R (Ohm) | D1: 103R (Ohm) | E1: 104R (Ohm) | F1: 105R (Ohm) | G1: 106R (Ohm) | H1: 107R (Ohm) | I1: 108R (Ohm) | J1: 109R (Ohm) | K1: 110R (Ohm) | L1: 111R (Ohm) | M1: 112R (Ohm) | N1: 113R (Ohm) | O1: 114R (Ohm) | P1: 115R (Ohm) | Q1: 116R (Ohm) | R1: 117R (Ohm) | S1: 118R (Ohm)
A2: 0 | B2: 60.585297 | C2: 87.296597 | D2: 320.66872 | E2: 469.63923 | F2: 192.23793 | G2: 391.91631 | H2: 493.75646 | I2: 387.57295 | J2: 118.16404 | K2: 276.16098 | L2: 608.15338 | M2: 301.55396 | N2: 509.5507 | O2: 174.74027 | P2: 2.9914351 | Q2: 25.083769 | R2: 601.88498 | S2: 225.77877
A3: 4 | B3: 83.503874 | C3: 112.35723 | D3: 351.03533 | E3: 495.26703 | F3: 213.36663 | G3: 418.06474 | H3: 511.35093 | I3: 417.0076 | J3: 146.56708 | K3: 312.23852 | L3: 635.43286 | M3: 318.92616 | N3: 522.64282 | O3: 219.2805 | P3: 2.9925126 | Q3: 37.329052 | R3: 627.52843 | S3: 264.48674
A4: 8 | B4: 106.53643 | C4: 143.79347 | D4: 381.29268 | E4: 524.48575 | F4: 240.34901 | G4: 444.7557 | H4: 529.26496 | I4: 442.33484 | J4: 172.77907 | K4: 347.18493 | L4: 664.52967 | M4: 338.34643 | N4: 531.25741 | O4: 257.78406 | P4: 3.0387506 | Q4: 53.790575 | R4: 655.13439 | S4: 302.64849
A5: 12 | B5: 131.87673 | C5: 179.87211 | D5: 411.29504 | E5: 559.94276 | F5: 267.60645 | G5: 473.38332 | H5: 558.91662 | I5: 478.06475 | J5: 196.28422 | K5: 384.63765 | L5: 694.66887 | M5: 360.18416 | N5: 546.16035 | O5: 300.44701 | P5: 3.9049977 | Q5: 72.979323 | R5: 684.30837 | S5: 342.55736
A6: 16 | B6: 161.16332 | C6: 216.76042 | D6: 450.43844 | E6: 599.70437 | F6: 300.41095 | G6: 501.62406 | H6: 588.54593 | I6: 510.0622 | J6: 220.35775 | K6: 427.19439 | L6: 731.20312 | M6: 384.71876 | N6: 573.98113 | O6: 349.46785 | P6: 9.9247313 | Q6: 98.843364 | R6: 715.92455 | S6: 382.46693
A7: 20 | B7: 190.16184 | C7: 253.32873 | D7: 487.91881 | E7: 637.7547 | F7: 328.73951 | G7: 533.54467 | H7: 614.64385 | I7: 540.07456 | J7: 249.02206 | K7: 461.074 | L7: 761.37487 | M7: 404.32022 | N7: 598.65549 | O7: 394.57528 | P7: 14.677309 | Q7: 118.78864 | R7: 748.84001 | S7: 416.04257
A8: 30 | B8: 251.93636 | C8: 338.63287 | D8: 564.85854 | E8: 721.05535 | F8: 407.7705 | G8: 607.43004 | H8: 671.97014 | I8: 620.71385 | J8: 330.62024 | K8: 551.86535 | L8: 839.64467 | M8: 458.9019 | N8: 691.0042 | O8: 497.2903 | P8: 24.863588 | Q8: 170.27481 | R8: 833.9165 | S8: 509.16852
A9: 40 | B9: 321.98598 | C9: 410.84632 | D9: 634.66105 | E9: 799.11787 | F9: 469.62267 | G9: 661.57955 | H9: 745.83182 | I9: 694.27405 | J9: 407.27209 | K9: 619.49016 | L9: 899.33341 | M9: 506.15514 | N9: 802.47469 | O9: 585.84761 | P9: 52.912317 | Q9: 234.23111 | R9: 897.52951 | S9: 600.15287
A10: 60 | B10: 454.29967 | C10: 556.51257 | D10: 774.60767 | E10: 947.2756 | F10: 580.72623 | G10: 773.4128 | H10: 865.35052 | I10: 828.67376 | J10: 544.85724 | K10: 753.32077 | L10: 1005.019 | M10: 582.26087 | N10: 994.27704 | O10: 778.46613 | P10: 107.10221 | Q10: 384.65614 | R10: 1021.0569 | S10: 746.94819
